Workbook

Sheet 📊 Dashboard
A1: 🚒 DAMKAR — SISTEM PENDATAAN ASET | Dinas Pemadam Kebakaran Kota Luwu Timur
A2: 📅 Dibuat: 25 February 2026 | Total Posko: 10 | Sumber: DRAFF_PELAPORAN_ASET.docx
A4: 📦 Total Jenis Peralatan Terdaftar | D4: 🔧 Laporan Kerusakan/Hilang | G4: 🔄 Pengembalian Aset | J4: 🏠 Total Posko Aktif | M4: 📅 Update Terakhir
A6: =COUNTA('📦 Master Inventaris'!D:D)-1 -> 321 | D6: =COUNTA('🔧 Kerusakan'!A:A)-2 -> 4 | G6: =COUNTA('🔄 Pengembalian'!A:A)-2 -> 3 | J6: 10 | M6: =TEXT(TODAY(),"DD/MM/YYYY") -> 25/02/2026
A10: REKAP INVENTARIS PER POSKO
A11: No | B11: Nama Posko | C11: Total Jenis Alat | D11: Laporan Rusak | E11: Laporan Hilang | F11: Dipinjam | G11: Dikembalikan | H11: Total Laporan | I11: % Rusak/Hilang | J11: Kondisi | K11: Keterangan
A12: 1 | B12: Mako | C12: =COUNTIF('📦 Master Inventaris'!B:B,B12) -> 30 | D12: =COUNTIFS('🔧 Kerusakan'!E:E,B12,'🔧 Kerusakan'!H:H,"RUSAK") -> 0 | E12: =COUNTIFS('🔧 Kerusakan'!E:E,B12,'🔧 Kerusakan'!H:H,"HILANG") -> 0 | F12: =COUNTIFS('🔧 Kerusakan'!E:E,B12,'🔧 Kerusakan'!H:H,"DIPINJAM") -> 0 | G12: =COUNTIF('🔄 Pengembalian'!G:G,B12) -> 0 | H12: =D12+E12+F12+G12 -> 0 | I12: =IFERROR((D12+E12)/MAX(H12,1),0) -> 0 | J12: =IF(D12+E12=0,"✅ Normal",IF(D12+E12<=2,"⚠️ Perhatian","🚨 Kritis")) -> ✅ Normal | K12: -
A13: 2 | B13: Kalaena | C13: =COUNTIF('📦 Master Inventaris'!B:B,B13) -> 34 | D13: =COUNTIFS('🔧 Kerusakan'!E:E,B13,'🔧 Kerusakan'!H:H,"RUSAK") -> 0 | E13: =COUNTIFS('🔧 Kerusakan'!E:E,B13,'🔧 Kerusakan'!H:H,"HILANG") -> 0 | F13: =COUNTIFS('🔧 Kerusakan'!E:E,B13,'🔧 Kerusakan'!H:H,"DIPINJAM") -> 0 | G13: =COUNTIF('🔄 Pengembalian'!G:G,B13) -> 0 | H13: =D13+E13+F13+G13 -> 0 | I13: =IFERROR((D13+E13)/MAX(H13,1),0) -> 0 | J13: =IF(D13+E13=0,"✅ Normal",IF(D13+E13<=2,"⚠️ Perhatian","🚨 Kritis")) -> ✅ Normal | K13: -
A14: 3 | B14: Angkona | C14: =COUNTIF('📦 Master Inventaris'!B:B,B14) -> 33 | D14: =COUNTIFS('🔧 Kerusakan'!E:E,B14,'🔧 Kerusakan'!H:H,"RUSAK") -> 0 | E14: =COUNTIFS('🔧 Kerusakan'!E:E,B14,'🔧 Kerusakan'!H:H,"HILANG") -> 0 | F14: =COUNTIFS('🔧 Kerusakan'!E:E,B14,'🔧 Kerusakan'!H:H,"DIPINJAM") -> 0 | G14: =COUNTIF('🔄 Pengembalian'!G:G,B14) -> 0 | H14: =D14+E14+F14+G14 -> 0 | I14: =IFERROR((D14+E14)/MAX(H14,1),0) -> 0 | J14: =IF(D14+E14=0,"✅ Normal",IF(D14+E14<=2,"⚠️ Perhatian","🚨 Kritis")) -> ✅ Normal | K14: -
A15: 4 | B15: Tomoni | C15: =COUNTIF('📦 Master Inventaris'!B:B,B15) -> 43 | D15: =COUNTIFS('🔧 Kerusakan'!E:E,B15,'🔧 Kerusakan'!H:H,"RUSAK") -> 0 | E15: =COUNTIFS('🔧 Kerusakan'!E:E,B15,'🔧 Kerusakan'!H:H,"HILANG") -> 0 | F15: =COUNTIFS('🔧 Kerusakan'!E:E,B15,'🔧 Kerusakan'!H:H,"DIPINJAM") -> 0 | G15: =COUNTIF('🔄 Pengembalian'!G:G,B15) -> 1 | H15: =D15+E15+F15+G15 -> 1 | I15: =IFERROR((D15+E15)/MAX(H15,1),0) -> 0 | J15: =IF(D15+E15=0,"✅ Normal",IF(D15+E15<=2,"⚠️ Perhatian","🚨 Kritis")) -> ✅ Normal | K15: -
A16: 5 | B16: Wasuponda | C16: =COUNTIF('📦 Master Inventaris'!B:B,B16) -> 30 | D16: =COUNTIFS('🔧 Kerusakan'!E:E,B16,'🔧 Kerusakan'!H:H,"RUSAK") -> 0 | E16: =COUNTIFS('🔧 Kerusakan'!E:E,B16,'🔧 Kerusakan'!H:H,"HILANG") -> 0 | F16: =COUNTIFS('🔧 Kerusakan'!E:E,B16,'🔧 Kerusakan'!H:H,"DIPINJAM") -> 0 | G16: =COUNTIF('🔄 Pengembalian'!G:G,B16) -> 0 | H16: =D16+E16+F16+G16 -> 0 | I16: =IFERROR((D16+E16)/MAX(H16,1),0) -> 0 | J16: =IF(D16+E16=0,"✅ Normal",IF(D16+E16<=2,"⚠️ Perhatian","🚨 Kritis")) -> ✅ Normal | K16: -
A17: 6 | B17: Baruga | C17: =COUNTIF('📦 Master Inventaris'!B:B,B17) -> 29 | D17: =COUNTIFS('🔧 Kerusakan'!E:E,B17,'🔧 Kerusakan'!H:H,"RUSAK") -> 0 | E17: =COUNTIFS('🔧 Kerusakan'!E:E,B17,'🔧 Kerusakan'!H:H,"HILANG") -> 0 | F17: =COUNTIFS('🔧 Kerusakan'!E:E,B17,'🔧 Kerusakan'!H:H,"DIPINJAM") -> 0 | G17: =COUNTIF('🔄 Pengembalian'!G:G,B17) -> 0 | H17: =D17+E17+F17+G17 -> 0 | I17: =IFERROR((D17+E17)/MAX(H17,1),0) -> 0 | J17: =IF(D17+E17=0,"✅ Normal",IF(D17+E17<=2,"⚠️ Perhatian","🚨 Kritis")) -> ✅ Normal | K17: -
A18: 7 | B18: Burau | C18: =COUNTIF('📦 Master Inventaris'!B:B,B18) -> 32 | D18: =COUNTIFS('🔧 Kerusakan'!E:E,B18,'🔧 Kerusakan'!H:H,"RUSAK") -> 0 | E18: =COUNTIFS('🔧 Kerusakan'!E:E,B18,'🔧 Kerusakan'!H:H,"HILANG") -> 0 | F18: =COUNTIFS('🔧 Kerusakan'!E:E,B18,'🔧 Kerusakan'!H:H,"DIPINJAM") -> 0 | G18: =COUNTIF('🔄 Pengembalian'!G:G,B18) -> 1 | H18: =D18+E18+F18+G18 -> 1 | I18: =IFERROR((D18+E18)/MAX(H18,1),0) -> 0 | J18: =IF(D18+E18=0,"✅ Normal",IF(D18+E18<=2,"⚠️ Perhatian","🚨 Kritis")) -> ✅ Normal | K18: -
A19: 8 | B19: Wotu | C19: =COUNTIF('📦 Master Inventaris'!B:B,B19) -> 30 | D19: =COUNTIFS('🔧 Kerusakan'!E:E,B19,'🔧 Kerusakan'!H:H,"RUSAK") -> 0 | E19: =COUNTIFS('🔧 Kerusakan'!E:E,B19,'🔧 Kerusakan'!H:H,"HILANG") -> 0 | F19: =COUNTIFS('🔧 Kerusakan'!E:E,B19,'🔧 Kerusakan'!H:H,"DIPINJAM") -> 0 | G19: =COUNTIF('🔄 Pengembalian'!G:G,B19) -> 0 | H19: =D19+E19+F19+G19 -> 0 | I19: =IFERROR((D19+E19)/MAX(H19,1),0) -> 0 | J19: =IF(D19+E19=0,"✅ Normal",IF(D19+E19<=2,"⚠️ Perhatian","🚨 Kritis")) -> ✅ Normal | K19: -
A20: 9 | B20: Tomoni Timur | C20: =COUNTIF('📦 Master Inventaris'!B:B,B20) -> 30 | D20: =COUNTIFS('🔧 Kerusakan'!E:E,B20,'🔧 Kerusakan'!H:H,"RUSAK") -> 0 | E20: =COUNTIFS('🔧 Kerusakan'!E:E,B20,'🔧 Kerusakan'!H:H,"HILANG") -> 0 | F20: =COUNTIFS('🔧 Kerusakan'!E:E,B20,'🔧 Kerusakan'!H:H,"DIPINJAM") -> 0 | G20: =COUNTIF('🔄 Pengembalian'!G:G,B20) -> 0 | H20: =D20+E20+F20+G20 -> 0 | I20: =IFERROR((D20+E20)/MAX(H20,1),0) -> 0 | J20: =IF(D20+E20=0,"✅ Normal",IF(D20+E20<=2,"⚠️ Perhatian","🚨 Kritis")) -> ✅ Normal | K20: -
A21: 10 | B21: Towuti | C21: =COUNTIF('📦 Master Inventaris'!B:B,B21) -> 30 | D21: =COUNTIFS('🔧 Kerusakan'!E:E,B21,'🔧 Kerusakan'!H:H,"RUSAK") -> 0 | E21: =COUNTIFS('🔧 Kerusakan'!E:E,B21,'🔧 Kerusakan'!H:H,"HILANG") -> 0 | F21: =COUNTIFS('🔧 Kerusakan'!E:E,B21,'🔧 Kerusakan'!H:H,"DIPINJAM") -> 0 | G21: =COUNTIF('🔄 Pengembalian'!G:G,B21) -> 0 | H21: =D21+E21+F21+G21 -> 0 | I21: =IFERROR((D21+E21)/MAX(H21,1),0) -> 0 | J21: =IF(D21+E21=0,"✅ Normal",IF(D21+E21<=2,"⚠️ Perhatian","🚨 Kritis")) -> ✅ Normal | K21: -
B22: TOTAL KESELURUHAN | C22: =SUM(C12:C21) -> 321 | D22: =SUM(D12:D21) -> 0 | E22: =SUM(E12:E21) -> 0 | F22: =SUM(F12:F21) -> 0 | G22: =SUM(G12:G21) -> 2 | H22: =SUM(H12:H21) -> 2 | I22: =IFERROR((D22+E22)/MAX(H22,1),0) -> 0

Sheet 📦 Master Inventaris
A1: 📦 MASTER INVENTARIS PERALATAN — SEMUA POSKO | DAMKAR Kota Luwu Timur
A2: Data inventaris seluruh posko berdasarkan dokumen resmi. Kolom Jumlah & Tahun diisi oleh operator masing-masing posko.
A4: No | B4: Nama Posko | C4: Kode Posko | D4: Nama Peralatan | E4: Merk / Type | F4: Jumlah | G4: Satuan | H4: Tahun Pengadaan | I4: Kondisi Awal | J4: Status Saat Ini | K4: Keterangan | L4: No. Seri / Kode Aset
A5: 🏠 POSKO MAKO (30 jenis peralatan terdaftar)
A6: 1 | B6: Mako | C6: MKO | D6: Handy Talky | E6: Icom / VHF Transceiver | G6: Unit | I6: Baik | J6: Aktif | L6: MKO-001
A7: 2 | B7: Mako | C7: MKO | D7: Selang Penyemprot Air 1.5" | E7: Sintex | G7: Unit | I7: Baik | J7: Aktif | L7: MKO-002
A8: 3 | B8: Mako | C8: MKO | D8: Selang Penyemprot Air 2.5" | E8: Sintex | G8: Unit | I8: Baik | J8: Aktif | L8: MKO-003
A9: 4 | B9: Mako | C9: MKO | D9: APAR / Alat Pemadam Portable | E9: Phoenix / P-6P | G9: Unit | I9: Baik | J9: Aktif | L9: MKO-004
A10: 5 | B10: Mako | C10: MKO | D10: Helm Rescue | E10: Anti Benturan | G10: Unit | I10: Baik | J10: Aktif | L10: MKO-005
A11: 6 | B11: Mako | C11: MKO | D11: Helm Safety | E11: Anti Benturan | G11: Unit | I11: Baik | J11: Aktif | L11: MKO-006
A12: 7 | B12: Mako | C12: MKO | D12: Pakaian Panas/Lengkap | E12: Macino | G12: Unit | I12: Baik | J12: Aktif | L12: MKO-007
A13: 8 | B13: Mako | C13: MKO | D13: Pakaian Tahan Panas | E13: Macino | G13: Unit | I13: Baik | J13: Aktif | L13: MKO-008
A14: 9 | B14: Mako | C14: MKO | D14: Baju Safety Anti Lebah | E14: Lakeland | G14: Unit | I14: Baik | J14: Aktif | L14: MKO-009
A15: 10 | B15: Mako | C15: MKO | D15: Kaos Tangan Pemadam | E15: Viva | G15: Unit | I15: Baik | J15: Aktif | L15: MKO-010
A16: 11 | B16: Mako | C16: MKO | D16: Kaos Tangan Rescue | E16: Uno | G16: Unit | I16: Baik | J16: Aktif | L16: MKO-011
A17: 12 | B17: Mako | C17: MKO | D17: Sarung Tangan Anti Ular | E17: JJXF | G17: Unit | I17: Baik | J17: Aktif | L17: MKO-012
... A35: 30 | B35: Mako | C35: MKO | D35: Tool Kit Set | E35: Lokal | G35: Unit | I35: Baik | J35: Aktif | L35: MKO-030
A36: 🏠 POSKO KALAENA (34 jenis peralatan terdaftar)
A37: 1 | B37: Kalaena | C37: KLN | D37: Selang Penyemprot Air | E37: Sintex | G37: Unit | I37: Baik | J37: Aktif | L37: KLN-001
A38: 2 | B38: Kalaena | C38: KLN | D38: Transportable Water / Pompa Apung | E38: Aquafast | G38: Unit | I38: Baik | J38: Aktif | L38: KLN-002
A39: 3 | B39: Kalaena | C39: KLN | D39: Sepatu Safety | E39: Red Cobra | G39: Unit | I39: Baik | J39: Aktif | L39: KLN-003
A40: 4 | B40: Kalaena | C40: KLN | D40: Alat Pemadam / Portable (APAR) | E40: Macino | G40: Unit | I40: Baik | J40: Aktif | L40: KLN-004
A41: 5 | B41: Kalaena | C41: KLN | D41: Handy Talky | E41: Harvik | G41: Unit | I41: Baik | J41: Aktif | L41: KLN-005
A42: 6 | B42: Kalaena | C42: KLN | D42: Senter Penyelamatan | E42: Macino | G42: Unit | I42: Baik | J42: Aktif | L42: KLN-006
A43: 7 | B43: Kalaena | C43: KLN | D43: Penjepit Ular | E43: Phoenix / P-6P | G43: Unit | I43: Baik | J43: Aktif | L43: KLN-007
A44: 8 | B44: Kalaena | C44: KLN | D44: Pakaian Safety Anti Lebah | E44: Werwey | G44: Unit | I44: Baik | J44: Aktif | L44: KLN-008
A45: 9 | B45: Kalaena | C45: KLN | D45: Pakaian Tahan Panas | E45: Highigt Torchit | G45: Unit | I45: Baik | J45: Aktif | L45: KLN-009
A46: 10 | B46: Kalaena | C46: KLN | D46: Baju Anti Panas | E46: Fodalbet Snake | G46: Unit | I46: Baik | J46: Aktif | L46: KLN-010
A47: 11 | B47: Kalaena | C47: KLN | D47: Baju Safety Anti Panas | E47: Viva | G47: Unit | I47: Baik | J47: Aktif | L47: KLN-011
A48: 12 | B48: Kalaena | C48: KLN | D48: Kaos Tangan Pemadam | E48: Uno | G48: Unit | I48: Baik | J48: Aktif | L48: KLN-012
... A70: 34 | B70: Kalaena | C70: KLN | D70: Kacamata Safety | E70: Taffguard | G70: Unit | I70: Baik | J70: Aktif | L70: KLN-034
A71: 🏠 POSKO ANGKONA (33 jenis peralatan terdaftar)
A72: 1 | B72: Angkona | C72: AKN | D72: Pakaian Panas/Lengkap | E72: Pabrikan (Lokal) | G72: Unit | I72: Baik | J72: Aktif | L72: AKN-001
A73: 2 | B73: Angkona | C73: AKN | D73: Handy Talky | E73: Icom / VHF Transceiver | G73: Unit | I73: Baik | J73: Aktif | L73: AKN-002
A74: 3 | B74: Angkona | C74: AKN | D74: SSB Transportable | E74: Kenwood | G74: Unit | I74: Baik | J74: Aktif | L74: AKN-003
A75: 4 | B75: Angkona | C75: AKN | D75: Helm Fiber | E75: Anti Benturan | G75: Unit | I75: Baik | J75: Aktif | L75: AKN-004
A76: 5 | B76: Angkona | C76: AKN | D76: Selang Penyemprot Air | E76: Sintex | G76: Unit | I76: Baik | J76: Aktif | L76: AKN-005
A77: 6 | B77: Angkona | C77: AKN | D77: Lampu Sirine Tunggal | E77: Strobe Lightbar | G77: Unit | I77: Baik | J77: Aktif | L77: AKN-006
A78: 7 | B78: Angkona | C78: AKN | D78: Alat Pemadam/Portable (APAR) | E78: Macino | G78: Unit | I78: Baik | J78: Aktif | L78: AKN-007
A79: 8 | B79: Angkona | C79: AKN | D79: Sepatu Safety | E79: PHOENIX / P-6P | G79: Unit | I79: Baik | J79: Aktif | L79: AKN-008
...

Sheet 🏠 Mako
A1: 🏠 INVENTARIS POSKO MAKO | DAMKAR Kota Luwu Timur | Kode: MKO
A2: Posko: Mako | Total Jenis Peralatan: 30 | Terakhir Diperbarui: ___________ | Penanggung Jawab: ___________
A4: Total Jenis | C4: Total Rusak | E4: Total Hilang | G4: Kondisi Baik
A5: 30 | C5: =COUNTIFS('🔧 Kerusakan'!E:E,"Mako",'🔧 Kerusakan'!H:H,"RUSAK") -> 0 | E5: =COUNTIFS('🔧 Kerusakan'!E:E,"Mako",'🔧 Kerusakan'!H:H,"HILANG") -> 0 | G5: =COUNTIF(J8:J38,"Baik") -> 0
A7: No | B7: Kode Aset | C7: Nama Peralatan | D7: Merk / Type | E7: Jumlah | F7: Satuan | G7: Tahun Pengadaan | H7: Kondisi | I7: Status | J7: Keterangan Tambahan
A8: 1 | B8: MKO-001 | C8: Handy Talky | D8: Icom / VHF Transceiver | F8: Unit | H8: Baik | I8: Aktif
A9: 2 | B9: MKO-002 | C9: Selang Penyemprot Air 1.5" | D9: Sintex | F9: Unit | H9: Baik | I9: Aktif
A10: 3 | B10: MKO-003 | C10: Selang Penyemprot Air 2.5" | D10: Sintex | F10: Unit | H10: Baik | I10: Aktif
A11: 4 | B11: MKO-004 | C11: APAR / Alat Pemadam Portable | D11: Phoenix / P-6P | F11: Unit | H11: Baik | I11: Aktif
A12: 5 | B12: MKO-005 | C12: Helm Rescue | D12: Anti Benturan | F12: Unit | H12: Baik | I12: Aktif
A13: 6 | B13: MKO-006 | C13: Helm Safety | D13: Anti Benturan | F13: Unit | H13: Baik | I13: Aktif
A14: 7 | B14: MKO-007 | C14: Pakaian Panas/Lengkap | D14: Macino | F14: Unit | H14: Baik | I14: Aktif
A15: 8 | B15: MKO-008 | C15: Pakaian Tahan Panas | D15: Macino | F15: Unit | H15: Baik | I15: Aktif
A16: 9 | B16: MKO-009 | C16: Baju Safety Anti Lebah | D16: Lakeland | F16: Unit | H16: Baik | I16: Aktif
A17: 10 | B17: MKO-010 | C17: Kaos Tangan Pemadam | D17: Viva | F17: Unit | H17: Baik | I17: Aktif
A18: 11 | B18: MKO-011 | C18: Kaos Tangan Rescue | D18: Uno | F18: Unit | H18: Baik | I18: Aktif
A19: 12 | B19: MKO-012 | C19: Sarung Tangan Anti Ular | D19: JJXF | F19: Unit | H19: Baik | I19: Aktif
... A37: 30 | B37: MKO-030 | C37: Tool Kit Set | D37: Lokal | F37: Unit | H37: Baik | I37: Aktif
C38: TOTAL | E38: =SUM(E8:E37) -> 0

Sheet 🏠 Kalaena
A1: 🏠 INVENTARIS POSKO KALAENA | DAMKAR Kota Luwu Timur | Kode: KLN
A2: Posko: Kalaena | Total Jenis Peralatan: 34 | Terakhir Diperbarui: ___________ | Penanggung Jawab: ___________
A4: Total Jenis | C4: Total Rusak | E4: Total Hilang | G4: Kondisi Baik
A5: 34 | C5: =COUNTIFS('🔧 Kerusakan'!E:E,"Kalaena",'🔧 Kerusakan'!H:H,"RUSAK") -> 0 | E5: =COUNTIFS('🔧 Kerusakan'!E:E,"Kalaena",'🔧 Kerusakan'!H:H,"HILANG") -> 0 | G5: =COUNTIF(J8:J42,"Baik") -> 0
A7: No | B7: Kode Aset | C7: Nama Peralatan | D7: Merk / Type | E7: Jumlah | F7: Satuan | G7: Tahun Pengadaan | H7: Kondisi | I7: Status | J7: Keterangan Tambahan
A8: 1 | B8: KLN-001 | C8: Selang Penyemprot Air | D8: Sintex | F8: Unit | H8: Baik | I8: Aktif
A9: 2 | B9: KLN-002 | C9: Transportable Water / Pompa Apung | D9: Aquafast | F9: Unit | H9: Baik | I9: Aktif
A10: 3 | B10: KLN-003 | C10: Sepatu Safety | D10: Red Cobra | F10: Unit | H10: Baik | I10: Aktif
A11: 4 | B11: KLN-004 | C11: Alat Pemadam / Portable (APAR) | D11: Macino | F11: Unit | H11: Baik | I11: Aktif
A12: 5 | B12: KLN-005 | C12: Handy Talky | D12: Harvik | F12: Unit | H12: Baik | I12: Aktif
A13: 6 | B13: KLN-006 | C13: Senter Penyelamatan | D13: Macino | F13: Unit | H13: Baik | I13: Aktif
A14: 7 | B14: KLN-007 | C14: Penjepit Ular | D14: Phoenix / P-6P | F14: Unit | H14: Baik | I14: Aktif
A15: 8 | B15: KLN-008 | C15: Pakaian Safety Anti Lebah | D15: Werwey | F15: Unit | H15: Baik | I15: Aktif
A16: 9 | B16: KLN-009 | C16: Pakaian Tahan Panas | D16: Highigt Torchit | F16: Unit | H16: Baik | I16: Aktif
A17: 10 | B17: KLN-010 | C17: Baju Anti Panas | D17: Fodalbet Snake | F17: Unit | H17: Baik | I17: Aktif
A18: 11 | B18: KLN-011 | C18: Baju Safety Anti Panas | D18: Viva | F18: Unit | H18: Baik | I18: Aktif
A19: 12 | B19: KLN-012 | C19: Kaos Tangan Pemadam | D19: Uno | F19: Unit | H19: Baik | I19: Aktif
... A41: 34 | B41: KLN-034 | C41: Kacamata Safety | D41: Taffguard | F41: Unit | H41: Baik | I41: Aktif
C42: TOTAL | E42: =SUM(E8:E41) -> 0

Sheet 🏠 Angkona
A1: 🏠 INVENTARIS POSKO ANGKONA | DAMKAR Kota Luwu Timur | Kode: AKN
A2: Posko: Angkona | Total Jenis Peralatan: 33 | Terakhir Diperbarui: ___________ | Penanggung Jawab: ___________
A4: Total Jenis | C4: Total Rusak | E4: Total Hilang | G4: Kondisi Baik
A5: 33 | C5: =COUNTIFS('🔧 Kerusakan'!E:E,"Angkona",'🔧 Kerusakan'!H:H,"RUSAK") -> 0 | E5: =COUNTIFS('🔧 Kerusakan'!E:E,"Angkona",'🔧 Kerusakan'!H:H,"HILANG") -> 0 | G5: =COUNTIF(J8:J41,"Baik") -> 0
A7: No | B7: Kode Aset | C7: Nama Peralatan | D7: Merk / Type | E7: Jumlah | F7: Satuan | G7: Tahun Pengadaan | H7: Kondisi | I7: Status | J7: Keterangan Tambahan
A8: 1 | B8: AKN-001 | C8: Pakaian Panas/Lengkap | D8: Pabrikan (Lokal) | F8: Unit | H8: Baik | I8: Aktif
A9: 2 | B9: AKN-002 | C9: Handy Talky | D9: Icom / VHF Transceiver | F9: Unit | H9: Baik | I9: Aktif
A10: 3 | B10: AKN-003 | C10: SSB Transportable | D10: Kenwood | F10: Unit | H10: Baik | I10: Aktif
A11: 4 | B11: AKN-004 | C11: Helm Fiber | D11: Anti Benturan | F11: Unit | H11: Baik | I11: Aktif
A12: 5 | B12: AKN-005 | C12: Selang Penyemprot Air | D12: Sintex | F12: Unit | H12: Baik | I12: Aktif
A13: 6 | B13: AKN-006 | C13: Lampu Sirine Tunggal | D13: Strobe Lightbar | F13: Unit | H13: Baik | I13: Aktif
A14: 7 | B14: AKN-007 | C14: Alat Pemadam/Portable (APAR) | D14: Macino | F14: Unit | H14: Baik | I14: Aktif
A15: 8 | B15: AKN-008 | C15: Sepatu Safety | D15: PHOENIX / P-6P | F15: Unit | H15: Baik | I15: Aktif
A16: 9 | B16: AKN-009 | C16: Telepon On/Off | D16: Harvik | F16: Unit | H16: Baik | I16: Aktif
A17: 10 | B17: AKN-010 | C17: Senter Penyelamatan | D17: MIYAKO | F17: Unit | H17: Baik | I17: Aktif
A18: 11 | B18: AKN-011 | C18: Penjepit Ular | D18: Nokia | F18: Unit | H18: Baik | I18: Aktif
A19: 12 | B19: AKN-012 | C19: Pakaian Safety Anti Lebah | D19: Highigt Torchit | F19: Unit | H19: Baik | I19: Aktif
... A40: 33 | B40: AKN-033 | C40: Sarung Tangan Anti Ular | D40: JJXF | F40: Unit | H40: Baik | I40: Aktif
C41: TOTAL | E41: =SUM(E8:E40) -> 0

Sheet 🏠 Tomoni
A1: 🏠 INVENTARIS POSKO TOMONI | DAMKAR Kota Luwu Timur | Kode: TMN
A2: Posko: Tomoni | Total Jenis Peralatan: 43 | Terakhir Diperbarui: ___________ | Penanggung Jawab: ___________
A4: Total Jenis | C4: Total Rusak | E4: Total Hilang | G4: Kondisi Baik
A5: 43 | C5: =COUNTIFS('🔧 Kerusakan'!E:E,"Tomoni",'🔧 Kerusakan'!H:H,"RUSAK") -> 0 | E5: =COUNTIFS('🔧 Kerusakan'!E:E,"Tomoni",'🔧 Kerusakan'!H:H,"HILANG") -> 0 | G5: =COUNTIF(J8:J51,"Baik") -> 0
A7: No | B7: Kode Aset | C7: Nama Peralatan | D7: Merk / Type | E7: Jumlah | F7: Satuan | G7: Tahun Pengadaan | H7: Kondisi | I7: Status | J7: Keterangan Tambahan
A8: 1 | B8: TMN-001 | C8: Selang Penyemprot Air | D8: Selang Sintex / 1.5-30m | F8: Unit | H8: Baik | I8: Aktif
A9: 2 | B9: TMN-002 | C9: Handy Talky | D9: Zeki | F9: Unit | H9: Baik | I9: Aktif
A10: 3 | B10: TMN-003 | C10: Tool Kit Set | D10: Icom / VHF Transceiver | F10: Unit | H10: Baik | I10: Aktif
A11: 4 | B11: TMN-004 | C11: Helm Fiber | D11: Wipro / 79 PCS | F11: Unit | H11: Baik | I11: Aktif
A12: 5 | B12: TMN-005 | C12: Respirator | D12: Jasmar | F12: Unit | H12: Baik | I12: Aktif
A13: 6 | B13: TMN-006 | C13: SSB Transportable | D13: Kenwood | F13: Unit | H13: Baik | I13: Aktif
A14: 7 | B14: TMN-007 | C14: Hidran Kebakaran | D14: Macino | F14: Unit | H14: Baik | I14: Aktif
A15: 8 | B15: TMN-008 | C15: Tabung APAR | D15: Phoenix / P-6P | F15: Unit | H15: Baik | I15: Aktif
A16: 9 | B16: TMN-009 | C16: Senter Kepala | D16: Fiber | F16: Unit | H16: Baik | I16: Aktif
A17: 10 | B17: TMN-010 | C17: Senter Penyelamatan | D17: Highigt Torchit | F17: Unit | H17: Baik | I17: Aktif
A18: 11 | B18: TMN-011 | C18: Senter | D18: Fodalbet Snake Tong | F18: Unit | H18: Baik | I18: Aktif
A19: 12 | B19: TMN-012 | C19: Telepon On/Off | D19: Viva | F19: Unit | H19: Baik | I19: Aktif
... A50: 43 | B50: TMN-043 | C50: Senter Kepala (Cadangan) | D50: Highigt Torchit | F50: Unit | H50: Baik | I50: Aktif
C51: TOTAL | E51: =SUM(E8:E50) -> 0

Sheet 🏠 Wasuponda
A1: 🏠 INVENTARIS POSKO WASUPONDA | DAMKAR Kota Luwu Timur | Kode: WSP
A2: Posko: Wasuponda | Total Jenis Peralatan: 30 | Terakhir Diperbarui: ___________ | Penanggung Jawab: ___________
A4: Total Jenis | C4: Total Rusak | E4: Total Hilang | G4: Kondisi Baik
A5: 30 | C5: =COUNTIFS('🔧 Kerusakan'!E:E,"Wasuponda",'🔧 Kerusakan'!H:H,"RUSAK") -> 0 | E5: =COUNTIFS('🔧 Kerusakan'!E:E,"Wasuponda",'🔧 Kerusakan'!H:H,"HILANG") -> 0 | G5: =COUNTIF(J8:J38,"Baik") -> 0
A7: No | B7: Kode Aset | C7: Nama Peralatan | D7: Merk / Type | E7: Jumlah | F7: Satuan | G7: Tahun Pengadaan | H7: Kondisi | I7: Status | J7: Keterangan Tambahan
A8: 1 | B8: WSP-001 | C8: Handy Talky | D8: Icom / VHF Transceiver | F8: Unit | H8: Baik | I8: Aktif
A9: 2 | B9: WSP-002 | C9: Selang Penyemprot Air 1.5" | D9: Sintex | F9: Unit | H9: Baik | I9: Aktif
A10: 3 | B10: WSP-003 | C10: Selang Penyemprot Air 2.5" | D10: Sintex | F10: Unit | H10: Baik | I10: Aktif
A11: 4 | B11: WSP-004 | C11: APAR / Alat Pemadam Portable | D11: Phoenix / P-6P | F11: Unit | H11: Baik | I11: Aktif
A12: 5 | B12: WSP-005 | C12: Helm Rescue | D12: Anti Benturan | F12: Unit | H12: Baik | I12: Aktif
A13: 6 | B13: WSP-006 | C13: Helm Safety | D13: Anti Benturan | F13: Unit | H13: Baik | I13: Aktif
A14: 7 | B14: WSP-007 | C14: Pakaian Panas/Lengkap | D14: Macino | F14: Unit | H14: Baik | I14: Aktif
A15: 8 | B15: WSP-008 | C15: Pakaian Tahan Panas | D15: Macino | F15: Unit | H15: Baik | I15: Aktif
A16: 9 | B16: WSP-009 | C16: Baju Safety Anti Lebah | D16: Lakeland | F16: Unit | H16: Baik | I16: Aktif
A17: 10 | B17: WSP-010 | C17: Kaos Tangan Pemadam | D17: Viva | F17: Unit | H17: Baik | I17: Aktif
A18: 11 | B18: WSP-011 | C18: Kaos Tangan Rescue | D18: Uno | F18: Unit | H18: Baik | I18: Aktif
A19: 12 | B19: WSP-012 | C19: Sarung Tangan Anti Ular | D19: JJXF | F19: Unit | H19: Baik | I19: Aktif
... A37: 30 | B37: WSP-030 | C37: Tool Kit Set | D37: Lokal | F37: Unit | H37: Baik | I37: Aktif
C38: TOTAL | E38: =SUM(E8:E37) -> 0

Sheet 🏠 Baruga
A1: 🏠 INVENTARIS POSKO BARUGA | DAMKAR Kota Luwu Timur | Kode: BRG
A2: Posko: Baruga | Total Jenis Peralatan: 29 | Terakhir Diperbarui: ___________ | Penanggung Jawab: ___________
A4: Total Jenis | C4: Total Rusak | E4: Total Hilang | G4: Kondisi Baik
A5: 29 | C5: =COUNTIFS('🔧 Kerusakan'!E:E,"Baruga",'🔧 Kerusakan'!H:H,"RUSAK") -> 0 | E5: =COUNTIFS('🔧 Kerusakan'!E:E,"Baruga",'🔧 Kerusakan'!H:H,"HILANG") -> 0 | G5: =COUNTIF(J8:J37,"Baik") -> 0
A7: No | B7: Kode Aset | C7: Nama Peralatan | D7: Merk / Type | E7: Jumlah | F7: Satuan | G7: Tahun Pengadaan | H7: Kondisi | I7: Status | J7: Keterangan Tambahan
A8: 1 | B8: BRG-001 | C8: Handy Talky | D8: Icom/VHF Transceiver | F8: Unit | H8: Baik | I8: Aktif
A9: 2 | B9: BRG-002 | C9: Unit Transceiver SSB Transportable | D9: Syntax | F9: Unit | H9: Baik | I9: Aktif
A10: 3 | B10: BRG-003 | C10: Penjepit Ulat | D10: Syntax Unidur | F10: Unit | H10: Baik | I10: Aktif
A11: 4 | B11: BRG-004 | C11: Life Jaket | D11: Machino Lianxing | F11: Unit | H11: Baik | I11: Aktif
A12: 5 | B12: BRG-005 | C12: Pakaian Safety Anti Lebah | D12: Machino | F12: Unit | H12: Baik | I12: Aktif
A13: 6 | B13: BRG-006 | C13: Pakaian Tahan Panas | D13: Suction Hose Spiral | F13: Unit | H13: Baik | I13: Aktif
A14: 7 | B14: BRG-007 | C14: Senter Kepala | D14: Kenwood | F14: Unit | H14: Baik | I14: Aktif
A15: 8 | B15: BRG-008 | C15: Senter Swat | D15: Fodalbelt Snake Tong | F15: Unit | H15: Baik | I15: Aktif
A16: 9 | B16: BRG-009 | C16: Sarung Tangan | D16: Gren | F16: Unit | H16: Baik | I16: Aktif
A17: 10 | B17: BRG-010 | C17: Kaos Tangan Pemadam | D17: Viva | F17: Unit | H17: Baik | I17: Aktif
A18: 11 | B18: BRG-011 | C18: Kaos Tangan Rescue | D18: Uno | F18: Unit | H18: Baik | I18: Aktif
A19: 12 | B19: BRG-012 | C19: Kaos Tangan Anti Ular | D19: JJXF | F19: Unit | H19: Baik | I19: Aktif
... A36: 29 | B36: BRG-029 | C36: Selang Penghisap Air | D36: Suction Hose | F36: Unit | H36: Baik | I36: Aktif
C37: TOTAL | E37: =SUM(E8:E36) -> 0

Sheet 🏠 Burau
A1: 🏠 INVENTARIS POSKO BURAU | DAMKAR Kota Luwu Timur | Kode: BRU
A2: Posko: Burau | Total Jenis Peralatan: 32 | Terakhir Diperbarui: ___________ | Penanggung Jawab: ___________
A4: Total Jenis | C4: Total Rusak | E4: Total Hilang | G4: Kondisi Baik
A5: 32 | C5: =COUNTIFS('🔧 Kerusakan'!E:E,"Burau",'🔧 Kerusakan'!H:H,"RUSAK") -> 0 | E5: =COUNTIFS('🔧 Kerusakan'!E:E,"Burau",'🔧 Kerusakan'!H:H,"HILANG") -> 0 | G5: =COUNTIF(J8:J40,"Baik") -> 0
A7: No | B7: Kode Aset | C7: Nama Peralatan | D7: Merk / Type | E7: Jumlah | F7: Satuan | G7: Tahun Pengadaan | H7: Kondisi | I7: Status | J7: Keterangan Tambahan
A8: 1 | B8: BRU-001 | C8: Selang Penyemprot Air | D8: Sintex | F8: Unit | H8: Baik | I8: Aktif
A9: 2 | B9: BRU-002 | C9: Handy Talky | D9: Red Cobra | F9: Unit | H9: Baik | I9: Aktif
A10: 3 | B10: BRU-003 | C10: Alat Pemadam Kebakaran Lain-lain | D10: Icom / VHF Transceiver | F10: Unit | H10: Baik | I10: Aktif
A11: 4 | B11: BRU-004 | C11: Pakaian Panas/Lengkap | D11: Water Stride | F11: Unit | H11: Baik | I11: Aktif
A12: 5 | B12: BRU-005 | C12: Pakaian Tahan Panas | D12: Pabrikan | F12: Unit | H12: Baik | I12: Aktif
A13: 6 | B13: BRU-006 | C13: Baju Safety Anti Panas | D13: Macino | F13: Unit | H13: Baik | I13: Aktif
A14: 7 | B14: BRU-007 | C14: Baju Pemadam | D14: Phoenix / 6 kg | F14: Unit | H14: Baik | I14: Aktif
A15: 8 | B15: BRU-008 | C15: Baju Anti Tawon | D15: Niosh | F15: Unit | H15: Baik | I15: Aktif
A16: 9 | B16: BRU-009 | C16: Alat Pemadam / Portable (APAR) | D16: Phoenix / 6 kg | F16: Unit | H16: Baik | I16: Aktif
A17: 10 | B17: BRU-010 | C17: Respirator | D17: Niosh | F17: Unit | H17: Baik | I17: Aktif
A18: 11 | B18: BRU-011 | C18: Penjepit Ular | D18: Fodalbet Snake Tong | F18: Unit | H18: Baik | I18: Aktif
A19: 12 | B19: BRU-012 | C19: Pakaian Safety Anti Lebah | D19: Viva | F19: Unit | H19: Baik | I19: Aktif
... A39: 32 | B39: BRU-032 | C39: Kaos Tangan Rescue | D39: Uno | F39: Unit | H39: Baik | I39: Aktif
C40: TOTAL | E40: =SUM(E8:E39) -> 0

Sheet 🏠 Wotu
A1: 🏠 INVENTARIS POSKO WOTU | DAMKAR Kota Luwu Timur | Kode: WTU
A2: Posko: Wotu | Total Jenis Peralatan: 30 | Terakhir Diperbarui: ___________ | Penanggung Jawab: ___________
A4: Total Jenis | C4: Total Rusak | E4: Total Hilang | G4: Kondisi Baik
A5: 30 | C5: =COUNTIFS('🔧 Kerusakan'!E:E,"Wotu",'🔧 Kerusakan'!H:H,"RUSAK") -> 0 | E5: =COUNTIFS('🔧 Kerusakan'!E:E,"Wotu",'🔧 Kerusakan'!H:H,"HILANG") -> 0 | G5: =COUNTIF(J8:J38,"Baik") -> 0
A7: No | B7: Kode Aset | C7: Nama Peralatan | D7: Merk / Type | E7: Jumlah | F7: Satuan | G7: Tahun Pengadaan | H7: Kondisi | I7: Status | J7: Keterangan Tambahan
A8: 1 | B8: WTU-001 | C8: Handy Talky | D8: Icom / VHF Transceiver | F8: Unit | H8: Baik | I8: Aktif
A9: 2 | B9: WTU-002 | C9: Selang Penyemprot Air 1.5" | D9: Sintex | F9: Unit | H9: Baik | I9: Aktif
A10: 3 | B10: WTU-003 | C10: Selang Penyemprot Air 2.5" | D10: Sintex | F10: Unit | H10: Baik | I10: Aktif
A11: 4 | B11: WTU-004 | C11: APAR / Alat Pemadam Portable | D11: Phoenix / P-6P | F11: Unit | H11: Baik | I11: Aktif
A12: 5 | B12: WTU-005 | C12: Helm Rescue | D12: Anti Benturan | F12: Unit | H12: Baik | I12: Aktif
A13: 6 | B13: WTU-006 | C13: Helm Safety | D13: Anti Benturan | F13: Unit | H13: Baik | I13: Aktif
A14: 7 | B14: WTU-007 | C14: Pakaian Panas/Lengkap | D14: Macino | F14: Unit | H14: Baik | I14: Aktif
A15: 8 | B15: WTU-008 | C15: Pakaian Tahan Panas | D15: Macino | F15: Unit | H15: Baik | I15: Aktif
A16: 9 | B16: WTU-009 | C16: Baju Safety Anti Lebah | D16: Lakeland | F16: Unit | H16: Baik | I16: Aktif
A17: 10 | B17: WTU-010 | C17: Kaos Tangan Pemadam | D17: Viva | F17: Unit | H17: Baik | I17: Aktif
A18: 11 | B18: WTU-011 | C18: Kaos Tangan Rescue | D18: Uno | F18: Unit | H18: Baik | I18: Aktif
A19: 12 | B19: WTU-012 | C19: Sarung Tangan Anti Ular | D19: JJXF | F19: Unit | H19: Baik | I19: Aktif
... A37: 30 | B37: WTU-030 | C37: Tool Kit Set | D37: Lokal | F37: Unit | H37: Baik | I37: Aktif
C38: TOTAL | E38: =SUM(E8:E37) -> 0

Sheet 🏠 Tomoni Timur
A1: 🏠 INVENTARIS POSKO TOMONI TIMUR | DAMKAR Kota Luwu Timur | Kode: TMT
A2: Posko: Tomoni Timur | Total Jenis Peralatan: 30 | Terakhir Diperbarui: ___________ | Penanggung Jawab: ___________
A4: Total Jenis | C4: Total Rusak | E4: Total Hilang | G4: Kondisi Baik
A5: 30 | C5: =COUNTIFS('🔧 Kerusakan'!E:E,"Tomoni Timur",'🔧 Kerusakan'!H:H,"RUSAK") -> 0 | E5: =COUNTIFS('🔧 Kerusakan'!E:E,"Tomoni Timur",'🔧 Kerusakan'!H:H,"HILANG") -> 0 | G5: =COUNTIF(J8:J38,"Baik") -> 0
A7: No | B7: Kode Aset | C7: Nama Peralatan | D7: Merk / Type | E7: Jumlah | F7: Satuan | G7: Tahun Pengadaan | H7: Kondisi | I7: Status | J7: Keterangan Tambahan
A8: 1 | B8: TMT-001 | C8: Handy Talky | D8: Icom / VHF Transceiver | F8: Unit | H8: Baik | I8: Aktif
A9: 2 | B9: TMT-002 | C9: Selang Penyemprot Air 1.5" | D9: Sintex | F9: Unit | H9: Baik | I9: Aktif
A10: 3 | B10: TMT-003 | C10: Selang Penyemprot Air 2.5" | D10: Sintex | F10: Unit | H10: Baik | I10: Aktif
A11: 4 | B11: TMT-004 | C11: APAR / Alat Pemadam Portable | D11: Phoenix / P-6P | F11: Unit | H11: Baik | I11: Aktif
A12: 5 | B12: TMT-005 | C12: Helm Rescue | D12: Anti Benturan | F12: Unit | H12: Baik | I12: Aktif
A13: 6 | B13: TMT-006 | C13: Helm Safety | D13: Anti Benturan | F13: Unit | H13: Baik | I13: Aktif
A14: 7 | B14: TMT-007 | C14: Pakaian Panas/Lengkap | D14: Macino | F14: Unit | H14: Baik | I14: Aktif
A15: 8 | B15: TMT-008 | C15: Pakaian Tahan Panas | D15: Macino | F15: Unit | H15: Baik | I15: Aktif
A16: 9 | B16: TMT-009 | C16: Baju Safety Anti Lebah | D16: Lakeland | F16: Unit | H16: Baik | I16: Aktif
A17: 10 | B17: TMT-010 | C17: Kaos Tangan Pemadam | D17: Viva | F17: Unit | H17: Baik | I17: Aktif
A18: 11 | B18: TMT-011 | C18: Kaos Tangan Rescue | D18: Uno | F18: Unit | H18: Baik | I18: Aktif
A19: 12 | B19: TMT-012 | C19: Sarung Tangan Anti Ular | D19: JJXF | F19: Unit | H19: Baik | I19: Aktif
... A37: 30 | B37: TMT-030 | C37: Tool Kit Set | D37: Lokal | F37: Unit | H37: Baik | I37: Aktif
C38: TOTAL | E38: =SUM(E8:E37) -> 0

Sheet 🏠 Towuti
A1: 🏠 INVENTARIS POSKO TOWUTI | DAMKAR Kota Luwu Timur | Kode: TWI
A2: Posko: Towuti | Total Jenis Peralatan: 30 | Terakhir Diperbarui: ___________ | Penanggung Jawab: ___________
A4: Total Jenis | C4: Total Rusak | E4: Total Hilang | G4: Kondisi Baik
A5: 30 | C5: =COUNTIFS('🔧 Kerusakan'!E:E,"Towuti",'🔧 Kerusakan'!H:H,"RUSAK") -> 0 | E5: =COUNTIFS('🔧 Kerusakan'!E:E,"Towuti",'🔧 Kerusakan'!H:H,"HILANG") -> 0 | G5: =COUNTIF(J8:J38,"Baik") -> 0
A7: No | B7: Kode Aset | C7: Nama Peralatan | D7: Merk / Type | E7: Jumlah | F7: Satuan | G7: Tahun Pengadaan | H7: Kondisi | I7: Status | J7: Keterangan Tambahan
A8: 1 | B8: TWI-001 | C8: Handy Talky | D8: Icom / VHF Transceiver | F8: Unit | H8: Baik | I8: Aktif
A9: 2 | B9: TWI-002 | C9: Selang Penyemprot Air 1.5" | D9: Sintex | F9: Unit | H9: Baik | I9: Aktif
A10: 3 | B10: TWI-003 | C10: Selang Penyemprot Air 2.5" | D10: Sintex | F10: Unit | H10: Baik | I10: Aktif
A11: 4 | B11: TWI-004 | C11: APAR / Alat Pemadam Portable | D11: Phoenix / P-6P | F11: Unit | H11: Baik | I11: Aktif
A12: 5 | B12: TWI-005 | C12: Helm Rescue | D12: Anti Benturan | F12: Unit | H12: Baik | I12: Aktif
A13: 6 | B13: TWI-006 | C13: Helm Safety | D13: Anti Benturan | F13: Unit | H13: Baik | I13: Aktif
A14: 7 | B14: TWI-007 | C14: Pakaian Panas/Lengkap | D14: Macino | F14: Unit | H14: Baik | I14: Aktif
A15: 8 | B15: TWI-008 | C15: Pakaian Tahan Panas | D15: Macino | F15: Unit | H15: Baik | I15: Aktif
A16: 9 | B16: TWI-009 | C16: Baju Safety Anti Lebah | D16: Lakeland | F16: Unit | H16: Baik | I16: Aktif
A17: 10 | B17: TWI-010 | C17: Kaos Tangan Pemadam | D17: Viva | F17: Unit | H17: Baik | I17: Aktif
A18: 11 | B18: TWI-011 | C18: Kaos Tangan Rescue | D18: Uno | F18: Unit | H18: Baik | I18: Aktif
A19: 12 | B19: TWI-012 | C19: Sarung Tangan Anti Ular | D19: JJXF | F19: Unit | H19: Baik | I19: Aktif
... A37: 30 | B37: TWI-030 | C37: Tool Kit Set | D37: Lokal | F37: Unit | H37: Baik | I37: Aktif
C38: TOTAL | E38: =SUM(E8:E37) -> 0

Sheet ✅ Pendaftaran Baru
A1: ✅ FORM PENDAFTARAN PERALATAN BARU | DAMKAR Kota Luwu Timur
A2: =TEXT(TODAY(),"DD MMMM YYYY") & " | Total Data: " & COUNTA(A5:A9999) & " entri" -> 25 February 2026 | Total Data: 3 entri
A4: No | B4: Timestamp | C4: Nama Posko | D4: Kode Posko | E4: Nama Peralatan | F4: Merk / Type | G4: Merk Lain | H4: Jumlah | I4: Satuan | J4: Tahun Pengadaan | K4: Link Foto / Bukti
A5: 1 | B5: =TEXT(NOW(),"DD/MM/YYYY HH:MM") -> 25/02/2026 00:24 | C5: Baruga | D5: BRG | E5: APAR 6 kg | F5: Phoenix / P-6P | H5: 3 | I5: Unit | J5: 2024 | K5: https://drive.google.com/...
A6: 2 | B6: =TEXT(NOW(),"DD/MM/YYYY HH:MM") -> 25/02/2026 00:24 | C6: Angkona | D6: AKN | E6: Helm Rescue | F6: Anti Benturan | H6: 5 | I6: Unit | J6: 2024 | K6: https://drive.google.com/...
A7: 3 | B7: =TEXT(NOW(),"DD/MM/YYYY HH:MM") -> 25/02/2026 00:24 | C7: Kalaena | D7: KLN | E7: Selang 1.5" | F7: Sintex | H7: 2 | I7: Meter | J7: 2023 | K7: https://drive.google.com/...

Sheet 🔧 Kerusakan
A1: 🔧 LAPORAN KERUSAKAN / KEHILANGAN / PEMINJAMAN | DAMKAR Kota Luwu Timur
A2: =TEXT(TODAY(),"DD MMMM YYYY") & " | Total Laporan: " & COUNTA(A5:A9999) & " entri" -> 25 February 2026 | Total Laporan: 3 entri
A4: No | B4: Timestamp | C4: Tanggal Laporan | D4: Waktu Laporan | E4: Nama Posko | F4: Nama Pelapor | G4: Nama Peralatan | H4: Kode Aset | I4: Status Aset | J4: Tingkat Kerusakan | K4: Jumlah | L4: Deskripsi Kejadian | M4: Tindakan Sementara
A5: 1 | B5: =TEXT(NOW(),"DD/MM/YYYY HH:MM") -> 25/02/2026 00:24 | C5: 25/02/2026 | D5: 08:30 | E5: Burau | F5: Ahmad Rizki | G5: Handy Talky | H5: BRU-002 | I5: RUSAK | J5: Berat | K5: 1 | L5: HT terjatuh saat operasi padamkan api | M5: Mengirim ke bengkel
A6: 2 | B6: =TEXT(NOW(),"DD/MM/YYYY HH:MM") -> 25/02/2026 00:24 | C6: 25/02/2026 | D6: 09:15 | E6: Tomoni | F6: Budi Santoso | G6: APAR 6 kg | H6: TMN-008 | I6: HILANG | J6: - | K6: 1 | L6: APAR tidak ditemukan di posko | M6: Lapor ke kepala posko
A7: 3 | B7: =TEXT(NOW(),"DD/MM/YYYY HH:MM") -> 25/02/2026 00:24 | C7: 24/02/2026 | D7: 14:00 | E7: Angkona | F7: Sandi Putra | G7: Selang 1.5" | H7: AKN-005 | I7: RUSAK | J7: Sedang | K7: 1 | L7: Selang retak di bagian tengah | M7: Ditambal sementara

Sheet 🔄 Pengembalian
A1: 🔄 LAPORAN PENGEMBALIAN ASET ANTAR POSKO | DAMKAR Kota Luwu Timur
A2: =TEXT(TODAY(),"DD MMMM YYYY") & " | Total Pengembalian: " & COUNTA(A5:A9999) & " entri" -> 25 February 2026 | Total Pengembalian: 2 entri
A4: No | B4: Timestamp | C4: Tgl Pengembalian | D4: Waktu | E4: Petugas Melaporkan | F4: Petugas Menerima | G4: Posko Peminjam | H4: Posko Asal Pemilik | I4: Nama Peralatan | J4: Jumlah | K4: Kondisi Dikembalikan | L4: Link Foto
A5: 1 | B5: =TEXT(NOW(),"DD/MM/YYYY HH:MM") -> 25/02/2026 00:24 | C5: 23/02/2026 | D5: 10:00 | E5: Rahmat | F5: Arif Hidayat | G5: Burau | H5: Baruga | I5: Selang 1.5" | J5: 2 | K5: Baik / Normal | L5: https://drive.google.com/...
A6: 2 | B6: =TEXT(NOW(),"DD/MM/YYYY HH:MM") -> 25/02/2026 00:24 | C6: 22/02/2026 | D6: 15:30 | E6: Surya | F6: Dedi Kurniawan | G6: Tomoni | H6: Kalaena | I6: APAR 6 kg | J6: 1 | K6: Rusak Ringan | L6: https://drive.google.com/...

Sheet 📈 Rekap & Analisis
A1: 📈 REKAP DAN ANALISIS LAPORAN | DAMKAR Kota Luwu Timur
A3: REKAP LAPORAN KERUSAKAN PER POSKO
A4: No | B4: Nama Posko | C4: Total Rusak | D4: Total Hilang | E4: Total Dipinjam | F4: Sudah Dikembalikan | G4: Belum Dikembalikan | H4: Total Laporan | I4: % Rusak | J4: % Hilang | K4: Skor Risiko | L4: Rekomendasi
A5: 1 | B5: Mako | C5: =COUNTIFS('🔧 Kerusakan'!E:E,B5,'🔧 Kerusakan'!I:I,"RUSAK") -> 0 | D5: =COUNTIFS('🔧 Kerusakan'!E:E,B5,'🔧 Kerusakan'!I:I,"HILANG") -> 0 | E5: =COUNTIFS('🔧 Kerusakan'!E:E,B5,'🔧 Kerusakan'!I:I,"DIPINJAM") -> 0 | F5: =COUNTIF('🔄 Pengembalian'!G:G,B5) -> 0 | G5: =E5-F5 -> 0 | H5: =C5+D5+E5 -> 0 | I5: =IFERROR(C5/MAX(H5,1),0) -> 0 | J5: =IFERROR(D5/MAX(H5,1),0) -> 0 | K5: =C5*3+D5*5+G5*2 -> 0 | L5: =IF(K5=0,"✅ Aman",IF(K5<=5,"⚠️ Monitor",IF(K5<=15,"🔴 Perhatian","🚨 Kritis"))) -> ✅ Aman
A6: 2 | B6: Kalaena | C6: =COUNTIFS('🔧 Kerusakan'!E:E,B6,'🔧 Kerusakan'!I:I,"RUSAK") -> 0 | D6: =COUNTIFS('🔧 Kerusakan'!E:E,B6,'🔧 Kerusakan'!I:I,"HILANG") -> 0 | E6: =COUNTIFS('🔧 Kerusakan'!E:E,B6,'🔧 Kerusakan'!I:I,"DIPINJAM") -> 0 | F6: =COUNTIF('🔄 Pengembalian'!G:G,B6) -> 0 | G6: =E6-F6 -> 0 | H6: =C6+D6+E6 -> 0 | I6: =IFERROR(C6/MAX(H6,1),0) -> 0 | J6: =IFERROR(D6/MAX(H6,1),0) -> 0 | K6: =C6*3+D6*5+G6*2 -> 0 | L6: =IF(K6=0,"✅ Aman",IF(K6<=5,"⚠️ Monitor",IF(K6<=15,"🔴 Perhatian","🚨 Kritis"))) -> ✅ Aman
A7: 3 | B7: Angkona | C7: =COUNTIFS('🔧 Kerusakan'!E:E,B7,'🔧 Kerusakan'!I:I,"RUSAK") -> 1 | D7: =COUNTIFS('🔧 Kerusakan'!E:E,B7,'🔧 Kerusakan'!I:I,"HILANG") -> 0 | E7: =COUNTIFS('🔧 Kerusakan'!E:E,B7,'🔧 Kerusakan'!I:I,"DIPINJAM") -> 0 | F7: =COUNTIF('🔄 Pengembalian'!G:G,B7) -> 0 | G7: =E7-F7 -> 0 | H7: =C7+D7+E7 -> 1 | I7: =IFERROR(C7/MAX(H7,1),0) -> 1 | J7: =IFERROR(D7/MAX(H7,1),0) -> 0 | K7: =C7*3+D7*5+G7*2 -> 3 | L7: =IF(K7=0,"✅ Aman",IF(K7<=5,"⚠️ Monitor",IF(K7<=15,"🔴 Perhatian","🚨 Kritis"))) -> ⚠️ Monitor
A8: 4 | B8: Tomoni | C8: =COUNTIFS('🔧 Kerusakan'!E:E,B8,'🔧 Kerusakan'!I:I,"RUSAK") -> 0 | D8: =COUNTIFS('🔧 Kerusakan'!E:E,B8,'🔧 Kerusakan'!I:I,"HILANG") -> 1 | E8: =COUNTIFS('🔧 Kerusakan'!E:E,B8,'🔧 Kerusakan'!I:I,"DIPINJAM") -> 0 | F8: =COUNTIF('🔄 Pengembalian'!G:G,B8) -> 1 | G8: =E8-F8 -> -1 | H8: =C8+D8+E8 -> 1 | I8: =IFERROR(C8/MAX(H8,1),0) -> 0 | J8: =IFERROR(D8/MAX(H8,1),0) -> 1 | K8: =C8*3+D8*5+G8*2 -> 3 | L8: =IF(K8=0,"✅ Aman",IF(K8<=5,"⚠️ Monitor",IF(K8<=15,"🔴 Perhatian","🚨 Kritis"))) -> ⚠️ Monitor
A9: 5 | B9: Wasuponda | C9: =COUNTIFS('🔧 Kerusakan'!E:E,B9,'🔧 Kerusakan'!I:I,"RUSAK") -> 0 | D9: =COUNTIFS('🔧 Kerusakan'!E:E,B9,'🔧 Kerusakan'!I:I,"HILANG") -> 0 | E9: =COUNTIFS('🔧 Kerusakan'!E:E,B9,'🔧 Kerusakan'!I:I,"DIPINJAM") -> 0 | F9: =COUNTIF('🔄 Pengembalian'!G:G,B9) -> 0 | G9: =E9-F9 -> 0 | H9: =C9+D9+E9 -> 0 | I9: =IFERROR(C9/MAX(H9,1),0) -> 0 | J9: =IFERROR(D9/MAX(H9,1),0) -> 0 | K9: =C9*3+D9*5+G9*2 -> 0 | L9: =IF(K9=0,"✅ Aman",IF(K9<=5,"⚠️ Monitor",IF(K9<=15,"🔴 Perhatian","🚨 Kritis"))) -> ✅ Aman
A10: 6 | B10: Baruga | C10: =COUNTIFS('🔧 Kerusakan'!E:E,B10,'🔧 Kerusakan'!I:I,"RUSAK") -> 0 | D10: =COUNTIFS('🔧 Kerusakan'!E:E,B10,'🔧 Kerusakan'!I:I,"HILANG") -> 0 | E10: =COUNTIFS('🔧 Kerusakan'!E:E,B10,'🔧 Kerusakan'!I:I,"DIPINJAM") -> 0 | F10: =COUNTIF('🔄 Pengembalian'!G:G,B10) -> 0 | G10: =E10-F10 -> 0 | H10: =C10+D10+E10 -> 0 | I10: =IFERROR(C10/MAX(H10,1),0) -> 0 | J10: =IFERROR(D10/MAX(H10,1),0) -> 0 | K10: =C10*3+D10*5+G10*2 -> 0 | L10: =IF(K10=0,"✅ Aman",IF(K10<=5,"⚠️ Monitor",IF(K10<=15,"🔴 Perhatian","🚨 Kritis"))) -> ✅ Aman
A11: 7 | B11: Burau | C11: =COUNTIFS('🔧 Kerusakan'!E:E,B11,'🔧 Kerusakan'!I:I,"RUSAK") -> 1 | D11: =COUNTIFS('🔧 Kerusakan'!E:E,B11,'🔧 Kerusakan'!I:I,"HILANG") -> 0 | E11: =COUNTIFS('🔧 Kerusakan'!E:E,B11,'🔧 Kerusakan'!I:I,"DIPINJAM") -> 0 | F11: =COUNTIF('🔄 Pengembalian'!G:G,B11) -> 1 | G11: =E11-F11 -> -1 | H11: =C11+D11+E11 -> 1 | I11: =IFERROR(C11/MAX(H11,1),0) -> 1 | J11: =IFERROR(D11/MAX(H11,1),0) -> 0 | K11: =C11*3+D11*5+G11*2 -> 1 | L11: =IF(K11=0,"✅ Aman",IF(K11<=5,"⚠️ Monitor",IF(K11<=15,"🔴 Perhatian","🚨 Kritis"))) -> ⚠️ Monitor
A12: 8 | B12: Wotu | C12: =COUNTIFS('🔧 Kerusakan'!E:E,B12,'🔧 Kerusakan'!I:I,"RUSAK") -> 0 | D12: =COUNTIFS('🔧 Kerusakan'!E:E,B12,'🔧 Kerusakan'!I:I,"HILANG") -> 0 | E12: =COUNTIFS('🔧 Kerusakan'!E:E,B12,'🔧 Kerusakan'!I:I,"DIPINJAM") -> 0 | F12: =COUNTIF('🔄 Pengembalian'!G:G,B12) -> 0 | G12: =E12-F12 -> 0 | H12: =C12+D12+E12 -> 0 | I12: =IFERROR(C12/MAX(H12,1),0) -> 0 | J12: =IFERROR(D12/MAX(H12,1),0) -> 0 | K12: =C12*3+D12*5+G12*2 -> 0 | L12: =IF(K12=0,"✅ Aman",IF(K12<=5,"⚠️ Monitor",IF(K12<=15,"🔴 Perhatian","🚨 Kritis"))) -> ✅ Aman
A13: 9 | B13: Tomoni Timur | C13: =COUNTIFS('🔧 Kerusakan'!E:E,B13,'🔧 Kerusakan'!I:I,"RUSAK") -> 0 | D13: =COUNTIFS('🔧 Kerusakan'!E:E,B13,'🔧 Kerusakan'!I:I,"HILANG") -> 0 | E13: =COUNTIFS('🔧 Kerusakan'!E:E,B13,'🔧 Kerusakan'!I:I,"DIPINJAM") -> 0 | F13: =COUNTIF('🔄 Pengembalian'!G:G,B13) -> 0 | G13: =E13-F13 -> 0 | H13: =C13+D13+E13 -> 0 | I13: =IFERROR(C13/MAX(H13,1),0) -> 0 | J13: =IFERROR(D13/MAX(H13,1),0) -> 0 | K13: =C13*3+D13*5+G13*2 -> 0 | L13: =IF(K13=0,"✅ Aman",IF(K13<=5,"⚠️ Monitor",IF(K13<=15,"🔴 Perhatian","🚨 Kritis"))) -> ✅ Aman
A14: 10 | B14: Towuti | C14: =COUNTIFS('🔧 Kerusakan'!E:E,B14,'🔧 Kerusakan'!I:I,"RUSAK") -> 0 | D14: =COUNTIFS('🔧 Kerusakan'!E:E,B14,'🔧 Kerusakan'!I:I,"HILANG") -> 0 | E14: =COUNTIFS('🔧 Kerusakan'!E:E,B14,'🔧 Kerusakan'!I:I,"DIPINJAM") -> 0 | F14: =COUNTIF('🔄 Pengembalian'!G:G,B14) -> 0 | G14: =E14-F14 -> 0 | H14: =C14+D14+E14 -> 0 | I14: =IFERROR(C14/MAX(H14,1),0) -> 0 | J14: =IFERROR(D14/MAX(H14,1),0) -> 0 | K14: =C14*3+D14*5+G14*2 -> 0 | L14: =IF(K14=0,"✅ Aman",IF(K14<=5,"⚠️ Monitor",IF(K14<=15,"🔴 Perhatian","🚨 Kritis"))) -> ✅ Aman
B15: TOTAL | C15: =SUM(C5:C14) -> 2 | D15: =SUM(D5:D14) -> 1 | E15: =SUM(E5:E14) -> 0 | F15: =SUM(F5:F14) -> 2 | G15: =SUM(G5:G14) -> -2 | H15: =SUM(H5:H14) -> 3 | I15: =SUM(I5:I14) -> 2 | J15: =SUM(J5:J14) -> 1 | K15: =SUM(K5:K14) -> 7
A17: LEGENDA KODE WARNA & STATUS
A18: ✅ AMAN | D18: Skor risiko = 0, tidak ada laporan kerusakan/kehilangan
A19: ⚠️ MONITOR | D19: Skor risiko 1-5, ada kerusakan ringan
A20: 🔴 PERHATIAN | D20: Skor risiko 6-15, kerusakan cukup banyak
A21: 🚨 KRITIS | D21: Skor risiko >15, perlu tindakan segera

Sheet ⚙️ Referensi
A1: ⚙️ SHEET REFERENSI — Data Master untuk Dropdown & Validasi
A3: NAMA POSKO | B3: STATUS ASET | C3: TINGKAT KERUSAKAN | D3: KONDISI BARANG | E3: STATUS INVENTARIS | F3: SATUAN
A4: Mako | B4: RUSAK | C4: Ringan | D4: Baik | E4: Aktif | F4: Unit
A5: Kalaena | B5: HILANG | C5: Sedang | D5: Rusak Ringan | E5: Rusak | F5: Buah
A6: Angkona | B6: DIPINJAM | C6: Berat | D6: Rusak Sedang | E6: Hilang | F6: Set
A7: Tomoni | C7: Rusak Total | D7: Rusak Berat | E7: Dipinjam | F7: Meter
A8: Wasuponda | C8: - | D8: Hilang | E8: Cadangan | F8: Pasang
A9: Baruga | E9: Dihapus | F9: Lembar
A10: Burau | F10: Kg
A11: Wotu | F11: Liter
A12: Tomoni Timur
A13: Towuti
A18: DAFTAR MERK / TYPE PERALATAN YANG TERDAFTAR
A19: No | B19: Merk / Type | C19: Kategori Umum
A20: 1 | B20: Alonco | C20: Umum
A21: 2 | B21: Andlesave | C21: Umum
A22: 3 | B22: Angus | C22: Umum
A23: 4 | B23: Anti Benturan | C23: Umum
A24: 5 | B24: Aquafast | C24: Umum
A25: 6 | B25: Atra | C25: Umum
A26: 7 | B26: Blue Eagle | C26: Umum
A27: 8 | B27: Catridge | C27: Umum
A28: 9 | B28: Endlessafe | C28: Umum
A29: 10 | B29: Eracom | C29: Umum
A30: 11 | B30: Escort | C30: Umum
A31: 12 | B31: Fodalbet Snake Tong | C31: Umum
... A69: 50 | B69: Zeki | C69: Umum

Sheet 📖 Panduan
A1: 📖 PANDUAN PENGGUNAAN SISTEM PENDATAAN ASET DAMKAR
A3: DAFTAR SHEET DAN FUNGSINYA
B4: Sheet | C4: Fungsi
B5: 📊 Dashboard | C5: Ringkasan semua data: KPI, rekap per posko, statistik cepat
B6: 📦 Master Inventaris | C6: Daftar lengkap seluruh peralatan semua 10 posko
B7: 🏠 [Nama Posko] | C7: Sheet khusus tiap posko (10 sheet, 1 per posko)
B8: ✅ Pendaftaran Baru | C8: Catat peralatan baru yang masuk ke posko
B9: 🔧 Kerusakan | C9: Laporan kerusakan, kehilangan, dan peminjaman aset
B10: 🔄 Pengembalian | C10: Laporan pengembalian aset antar posko
B11: 📈 Rekap & Analisis | C11: Analisis risiko dan rekap laporan kerusakan per posko
B12: ⚙️ Referensi | C12: Data master: nama posko, merk, status (jangan diubah sembarangan)
A14: CARA PENGGUNAAN
B15: 1. Pendaftaran Peralatan Baru
B16: Langkah: | C16: Buka sheet Pendaftaran Baru → Isi kolom yang kosong → Pilih Nama Posko dari dropdown → Isi Nama Peralatan, Merk, Jumlah, Tahun → Upload foto ke Google Drive dan paste link
B17: 2. Laporan Kerusakan/Hilang
B18: Langkah: | C18: Buka sheet Kerusakan → Isi semua kolom → Pilih Status: RUSAK/HILANG/DIPINJAM dari dropdown → Isi Tingkat Kerusakan → Deskripsikan kejadian dan tindakan sementara
B19: 3. Laporan Pengembalian Aset
B20: Langkah: | C20: Buka sheet Pengembalian → Isi data petugas yang melaporkan dan menerima → Pilih Posko Peminjam dan Posko Asal dari dropdown → Isi kondisi barang saat dikembalikan
A22: KODE ASET
B23: Format: | C23: [Kode Posko]-[Nomor Urut] | Contoh: BRG-001 = Baruga item ke-1
B24: Kode Posko: | C24: MKO=Mako | KLN=Kalaena | AKN=Angkona | TMN=Tomoni | WSP=Wasuponda | BRG=Baruga | BRU=Burau | WTU=Wotu | TMT=Tomoni Timur | TWI=Towuti
A26: CATATAN PENTING
B27: Jangan ubah sheet Referensi | C27: kecuali ada perubahan kebijakan. Sheet ini digunakan sebagai sumber dropdown.
B28: Backup rutin | C28: Lakukan backup file Excel ini setiap minggu ke Google Drive atau server.
B29: Integrasi Web | C29: Jika menggunakan Google Apps Script, setiap form submission otomatis mengisi sheet yang sesuai.
